<script src="../lib/fx.js"></script>

## async/await

<script>
  // 비동기 상황을 동기적인 문장으로 다루게끔 도와주는 키워드
  function delay(time) {
    return new Promise(resolve => setTimeout(() => resolve(), time));
  }

  async function delayIdentity(a) {
    await delay(500);
    return a;
  }

  // promise를 return 하겠다는 키워드
  async function f1() {
    // async 내부에서는 비동기 잡을 동기적으로 resolve해 처리
    const a = await delayIdentity(10);
    const b = await delayIdentity(5); // await: 프로미스 리턴하는 함수를 받아 resolve 기다리고, 내부값을 받아옴
    return a + b;
  }

  // const pa = Promise.resolve(10);
  const pa = f1();

  (async () => {
    // log(await pa); // await 키워드로 프로미스 내부값을 꺼내 쓸 수 있게 됨!
    // log(await pa);
    // log(await pa);
  })();
  // f1();
  // f1().then(log); // 프로미스이기 때문에 then 처리 가능
  // go(f1(), log);
  // (async () => {
  //   log(await f1());
  // }) ();
</script>

## QnA. Array.prototype.map이 있는데 왜 FxJS의 map 함수가 필요한지?

<script>
  function delayI(a) {
    return new Promise(resolve => setTimeout(() => resolve(a), 100));
  }

  async function f2() {
    const list = [1, 2, 3, 4];
    // 배열의 Map은 비동기 제어에 대한 처리가 없어, 해당 로직이 작동하지 않음.
    const temp = list.map(async a => await delayI(a * a));
    // log(temp); ~ 찍어보면 일반 배열에 프로미스 객체가 들어가 있음 (promise.all 쓰던가 돌면서 await 걸어야 Resolve값을 가져온다)
    //  [Promise {pending}, Promise {pending}..]
    const res = await temp;
    // log(res);
  }

  f2();

  async function f3() {
    const list = [1, 2, 3, 4];
    const temp = map(a => delayI(a * a), list);
    // log(temp); ~ 4개의 리졸브된 값들이 들어 있는 프로미스 찍힘! Promise {pending}
    const res = await temp;
    // log(res);
  }

  f3();

  // async 내부에서는 비동기를 동기처럼 다뤄지지만.
  function f4() {
    return map(a => delayI(a * a), [1, 2, 3, 4]);
  }

  // 호출하는 외부에서도 비동기에 대한 동기 처리 async awiat에 대해 걸어줘야 함
  (async () => {
    // 여기서도 프로미스를 받도록 해줘야 log가 잘 찍힌다!
    // log(await f4());
  })();
</script>

## QnA. 이제 비동기는 async/await로 제어할 수 있는데 왜 파이프라인이 필요한지?

<script>
  // 파이프라인: 함수 합성이 목적 (작은 단위함수로 유지보수 편하고, 조합으로 기능 구현!)
  // async-await: 비동기 상황을 동기적인 문장으로 다루는 목적
  function f5(list) {
    return go(list,
      L.map(a => delayI(a * a)),
      L.filter(a => delayI(a % 2)),
      L.map(a => delayI(a + 1)),
      C.take(2),
      reduce((a, b) => delayI(a + b)));
  }

  go(f5([1, 2, 3, 4, 5, 6, 7, 8]), a => log(a, 'f5'));

  async function f6(list) {
    let temp = [];
    for (const a of list) {
      const b = await delayI(a * a);
      if (await delayI(b % 2)) {
        const c = await delayI(b + 1);
        temp.push(c);
        if (temp.length == 2) break;
      }
    }
    let res = temp[0], i = 0;
    while (++i < temp.length) {
      res = await delayI(res + temp[i]);
    }
    return res;
  }

  go(f6([1, 2, 3, 4, 5, 6, 7, 8]), log);
</script>

## QnA. async/await와 파이프라인을 같이 사용하기도 하나요?

<script>
  async function f52(list) {
    const r1 = await go(list,
      L.map(a => delayI(a * a)),
      L.filter(a => delayI(a % 2)),
      L.map(a => delayI(a + 1)),
      C.take(2),
      reduce((a, b) => delayI(a + b)));

    const r2 = await go(list,
      L.map(a => delayI(a * a)),
      L.filter(a => delayI(a % 2)),
      reduce((a, b) => delayI(a + b)));

    // 함수형으로 만든 결과물을 동기적인 문장에 담아 다시 후처리!
    const r3 = await delayI(r1 + r2);

    return r3 + 10;
  }

  go(f52([1, 2, 3, 4, 5, 6, 7, 8]), a => log(a, 'f52'));
</script>

## QnA. 동기 상황에서 에러 핸들링은 어떻게 해야하는지?

<script>
  /*function f7(list) {
    try {
      return list
        .map(a => JSON.parse(a))
        .filter(a => a % 2)
        .slice(0, 2);
    } catch (e) {
      log(e);
      return []; // 한 콜스택에서 나는 에러를 잡아서 핸들링하는 방식!
    }
  }
  log(f7(['0', '1', '2', '{']));*/
</script>

## QnA. 비동기 상황에서 에러 핸들링은 어떻게 해야하는지?

<script>
  /*async function f8(list) {
    try {
      return await list // 이렇게 await를 걸어도 Array.map 자체가 promise 제어를 못하면서 에러를 잡지 못함..
        .map(async a => await new Promise(resolve => { // 일반적이 map에서는 프로미스를 제어하지 못해, 바깥의 catch에 에러가 안잡힘..
          resolve(JSON.parse(a));
        }))
        .filter(a => a % 2)
        .slice(0, 2);
    } catch (e) {
      // log(e, '----------------------');
      return [];
    }
  }
  f8(['0', '1', '2', '{']).then(log).catch(e => {
    log('에러 핸들링 하겠다.'); // 여기서도 잡히지 않는다..
  });*/
</script>

## QnA. 동기/비동기 에러 핸들링에서의 파이프라인의 이점은?

<script>
  async function f9(list) {
    try {
      // 1. 해당 부분에서 에러가 나면 Promise.reject('~~~') 로 떨어져야 함!
      // 2. go에 await을 걸어 promise 결과가 나오도록 강제 함 ~ 프로미스 안의 에러가 바로 return (await go 결과물)
      return await go(
        list,
        // 함수형에서 각 기능을 정의할때 Promise에 대한 처리를 해주면서, 에러가 바로 잡혀서 최상위 catch에서도 
        map(a => new Promise(resolve => {
          resolve(JSON.parse(a)); // promise 에러가 안잡히면, 잘 잡는 함수로 만들어줘야 한다!
        })),
        filter(a => a % 2),
        take(2));
    } catch (e) {
      return [];
    }
  }

  // f9(['0', '1', '2', '3', '4', '{']).then(a => log(a, 'f9')).catch(e => {
  //   log('에러 핸들링 하겠다.', e);
  // });
</script>
